<?xml version='1.0'?>

<robot name="myrobot">

<!-- +++++++++++++++++++++++Robot Definition+++++++++++++++++++++++++ /-->


<!--Chassis & Caster Wheel & Kinect Mount /-->
<link name="base_link">

<!--Chassis /-->
    <inertial>
        <origin xyz="0.0 0.0 0.0" rpy="0.0 0.0 0.0"/>
        <mass value="10"/>
        <inertia ixx="0.1" ixy="0.0" ixz="0.0" iyy="0.1" iyz="0.0" izz="0.1"/>
    </inertial>
    <visual name="base_link_visual">
        <origin xyz="0.0 0.0 0.0" rpy="0.0 0.0 0.0"/>
        <geometry>
            <box size="0.40 0.38 0.123"/>
        </geometry>
    </visual>
    <collision name="base_link_collision">
        <origin xyz="0.0 0.0 0.0" rpy="0.0 0.0 0.0"/>
        <geometry>
            <box size="0.0 0.0 0.0"/>
        </geometry>
    </collision>

<!--Caster Wheel /-->
    <visual name="caster_visual">
        <origin xyz="0.147 0.0 -0.0815" rpy="0.0 0.0 0.0"/>
        <geometry>
            <sphere radius="0.03"/>
        </geometry>
    </visual>
    <collision name='caster_collision'>
        <origin xyz="0.147 0.0 -0.0815" rpy="0.0 0.0 0.0"/>
        <geometry>
            <sphere radius="0.03"/>
        </geometry>
    </collision>

<!--Kinect Mount /-->
    <visual name="kinect_visual">
        <origin xyz="0.15 0.0 0.12" rpy="0.0 0.0 0.0"/>
        <geometry>
            <box size="0.06 0.10 0.12"/>
        </geometry>
    </visual>
    <collision name="kinect_collision">
        <origin xyz="0.15 0.0 0.12" rpy="0.0 0.0 0.0"/>
        <geometry>
            <box size="0.06 0.10 0.12"/>
        </geometry>
    </collision>

</link>


<!-- ++++++++++++++++Right wheel+++++++++++++++++++++++++++++++ /-->

<!-- Right wheel Link /-->
<link name="right_wheel">
    <inertial>
        <origin xyz="0.0 0.0 0.0" rpy="0 1.5707 1.5707"/>
        <mass value="0.0"/>
        <inertia ixx="0.1" ixy="0.0" ixz="0.0" iyy="0.1" iyz="0.0" izz="0.1"/>
    </inertial>
    <visual name="right_wheel_visual">
        <origin xyz="0.0 0.0 0.0" rpy="0 1.5707 1.5707"/>
        <geometry>
            <cylinder radius="0.06" length="0.06"/>
        </geometry>
    </visual>
    <collision>
        <origin xyz="0.0 0.0 0.0" rpy="0 1.5707 1.5707"/>
        <geometry>
            <cylinder radius="0.06" length="0.06"/>
        </geometry>
    </collision>
</link>

<!--Right wheel Joint /-->
<joint name="right_wheel_joint" type="continuous">
    <origin xyz="-0.08 -0.195 -0.0815" rpy="0.0 0.0 0.0"/>
    <parent link="base_link"/>
    <child link="right_wheel"/>
    <axis xyz="0 1 0"/>
    <limit effort="100" velocity="100"/>
    <dynamics damping="1.0" friction="1.0"/>
</joint>


<!-- ++++++++++++++++ Left wheel+++++++++++++++++++++++++++++++ /-->

<!-- Left wheel Link /-->
<link name="left_wheel">
    <inertial>
        <origin xyz="0.0 0.0 0.0" rpy="0 1.5707 1.5707"/>
        <mass value="0.0"/>
        <inertia ixx="0.1" ixy="0.0" ixz="0.0" iyy="0.1" iyz="0.0" izz="0.1"/>
    </inertial>
    <visual name="left_wheel_visual">
        <origin xyz="0.0 0.0 0.0" rpy="0 1.5707 1.5707"/>
        <geometry>
            <cylinder radius="0.06" length="0.06"/>
        </geometry>
    </visual>
    <collision>
        <origin xyz="0.0 0.0 0.0" rpy="0 1.5707 1.5707"/>
        <geometry>
            <cylinder radius="0.06" length="0.06"/>
        </geometry>
    </collision>
</link>

<!--Left wheel Joint /-->
<joint name="left_wheel_joint" type="continuous">
    <origin xyz="-0.08 0.195 -0.0815" rpy="0.0 0.0 0.0"/>
    <parent link="base_link"/>
    <child link="left_wheel"/>
    <axis xyz="0 1 0"/>
    <limit effort="100" velocity="100"/>
    <dynamics damping="1.0" friction="1.0"/>
</joint>

<!-- ++++++++++++++++++  Kinect  +++++++++++++++++++++++++++++ /-->
<!--kinect joint /-->

<joint name="kinect_joint" type="fixed">
    <origin xyz="0.18 0 .17" rpy="0 0 0"/>
    <parent link="base_link"/>
    <child link="camera_link"/>
</joint>


<!--Kinect  Link /-->
<link name="camera_link">

 <visual>
      <origin xyz="0 0 0.05" rpy="0 0 0"/>
      <geometry>
      <mesh filename="package://robo_description/meshes/kinect.dae"/>
      </geometry>
 </visual>

 <collision>
    <origin xyz="0 0 0" rpy="0 0 0"/>
    <geometry>
    <box size="0.1 0.1 0.1"/>
    </geometry>
 </collision>

 <inertial>
     <mass value="1e-5" />
     <origin xyz="0 0 0" rpy="0 0 0"/>
     <inertia ixx="1e-6" ixy="0" ixz="0" iyy="1e-6" iyz="0" izz="1e-6" />
 </inertial>


</link>




</robot>
