<?xml version='1.0'?>

<robot name="myrobot" xmlns:xacro="http://www.ros.org/wiki/xacro">
<xacro:include filename="$(find my_robot_description)/urdf/my_robot.gazebo" />

<!-- ******************Robot Definition***********************************  /-->

<!--Chassis & Caster Link /-->

 <link name='chassis'>

   <visual name='chassis_visual'>

      <origin xyz="0 0 0" rpy=" 0 0 0"/>

      <geometry>
        <box size=".4 .38 .10"/>
      </geometry>

    </visual>

   <inertial>

      <mass value="10.0"/>
      <origin xyz="0 0 0" rpy=" 0 0 0"/>
      <inertia
          ixx="0.5" ixy="0" ixz="0"
          iyy="1.0" iyz="0"
          izz="0.1"
      />

   </inertial>

   <collision name='collision'>
      <geometry>
        <box size=".4 .38 .10"/>
      </geometry>
   </collision>



 <collision name='caster_collision'>
    <origin xyz="0.17 0 -0.1" rpy=" 0 0 0"/>

    <geometry>
        <sphere radius="0.03"/>
    </geometry>

    <surface>

        <friction>
          <ode>
            <mu>0</mu>
            <mu2>0</mu2>
            <slip1>1.0</slip1>
            <slip2>1.0</slip2>
          </ode>
        </friction>

     </surface>

 </collision>

<visual name='caster_visual'>

     <origin xyz="0.17 0 -0.1" rpy=" 0 0 0"/>

     <geometry>
      <sphere radius="0.03"/>
     </geometry>

</visual>

</link>


<!-- ++++++++++++++++Left wheel+++++++++++++++++++++++++++++++ /-->


<!--left wheel Joint /-->

  <joint type="continuous" name="left_wheel_hinge">
    <origin xyz="-0.1 0.19 -0.03" rpy="0 0 0"/>
    <child link="left_wheel"/>
    <parent link="chassis"/>
    <axis xyz="0 1 0" rpy="0 0 0"/>
    <limit effort="100" velocity="100"/>
    <joint_properties damping="0.0" friction="0.0"/>
  </joint>



<!--left wheel Link /-->

 <link name="left_wheel">

    <visual name="left_wheel_visual">
      <origin xyz="0 0 0" rpy="0 1.5707 1.5707"/>
      <geometry>
        <cylinder radius="0.06" length="0.06"/>
      </geometry>
    </visual>


    <collision name="collision">
      <origin xyz="0 0 0" rpy="0 1.5707 1.5707"/>
      <geometry>
        <cylinder radius="0.06" length="0.06"/>
      </geometry>
    </collision>



    <inertial>
      <origin xyz="0 0 0" rpy="0 1.5707 1.5707"/>
      <mass value="5"/>
      <cylinder_inertia m="5" r="0.06" h="0.06"/>
      <inertia
        ixx="1.0" ixy="0.0" ixz="0.0"
        iyy="1.0" iyz="0.0"
        izz="1.0"/>
    </inertial>

 </link>

<!-- +++++++++++++++++++ Right Wheel +++++++++++++++++++++++++++++++++ /-->

<!--Right wheel joint/-->
  <joint type="continuous" name="right_wheel_hinge">

    <origin xyz="-0.1 -0.19 -0.03" rpy="0 0 0"/>

    <child link="right_wheel"/>
    <parent link="chassis"/>

    <axis xyz="0 1 0" rpy="0 0 0"/>

    <limit effort="100" velocity="100"/>

    <joint_properties damping="0.0" friction="0.0"/>

  </joint>

<!--Right Wheel link /-->

  <link name="right_wheel">

    <visual name="right_wheel_visual">

      <origin xyz="0 0 0" rpy="0 1.5707 1.5707"/>

      <geometry>
        <cylinder radius="0.06" length="0.06"/>
      </geometry>

    </visual>


    <collision name="collision">

      <origin xyz="0 0 0" rpy="0 1.5707 1.5707"/>

      <geometry>
        <cylinder radius="0.06" length="0.06"/>
      </geometry>

    </collision>


    <inertial>

      <origin xyz="0 0 0" rpy="0 1.5707 1.5707"/>
      <mass value="5"/>
      <cylinder_inertia m="5" r="0.06" h="0.06"/>

      <inertia
        ixx="1.0" ixy="0.0" ixz="0.0"
        iyy="1.0" iyz="0.0"
        izz="1.0"/>
      </inertial>

  </link>

<!-- ++++++++++++++++++  Kinect  +++++++++++++++++++++++++++++ /-->
<!--kinect joint /-->

<joint name="kinect_joint" type="fixed">

    <origin xyz=".15 0 .05" rpy="0 0 0"/>

    <parent link="chassis"/>
    <child link="camera_link"/>

</joint>


<!--Kinect  Link /-->

<link name="camera_link">

 <visual>

      <origin xyz="0 0 0.05" rpy="0 0 6.28"/>

      <geometry>

      <mesh filename="package://mybot_description/meshes/kinect.dae"/>

      </geometry>

 </visual>


 <collision>
    <origin xyz="0 0 0" rpy="0 0 6.28"/>

    <geometry>
    <box size="0.1 0.1 0.1"/>
    </geometry>

 </collision>

 <inertial>
     <mass value="1" />
     <origin xyz="0 0 0" rpy="0 0 6.28"/>
     <inertia ixx="1e-6" ixy="0" ixz="0" iyy="1e-6" iyz="0" izz="1e-6" />
 </inertial>


</link>



<!--  Kinect Optical Link and joints   /-->

<joint name="kinect_optical_joint" type="fixed">

<origin xyz="0 0 0" rpy="-1.5707 0 -1.5707"/> <!-- To invert the coordinates from image convention (Z is forward) to normal xyz /-->
<parent link="camera_link"/>
<child link="kinect_optical"/>
</joint>

<!--Virtual link to project the images to, and then flip it to us as its joint is flipped  /-->
<link name="kinect_optical">
</link>




</robot>
